<mujoco model="ant">
  <compiler inertiafromgeom="true" angle="degree"/>
  <option timestep="0.016" iterations="50" tolerance="1e-10" solver="Newton" jacobian="dense" cone="pyramidal"/>
  <default>
    <joint armature="1" damping="0.1" limited="true"/>
    <geom condim="3" density="5.0" friction="1.5 0.1 0.1" margin="0.01" rgba=".98 .54 .56 1."/>
  </default>
  <visual>
    <headlight ambient=".1 .1 .1" diffuse=".6 .6 .6" specular="0.3 0.3 0.3"/>
    <map znear=".01"/>
    <quality shadowsize="16384"/>
  </visual>
  <worldbody>
    <light cutoff="100" diffuse="1 1 1" dir="-0 0 -1.3" directional="true" exponent="1" pos="0 0 1.3" specular=".1 .1 .1"/>
    <geom condim="3" name="floor" pos="0 0 0" rgba="0.8 0.9 0.8 1" size="200 200 .125" type="plane" material="grid_new"/>
    <body name="0" pos="0 0 0">
      <camera name="track" mode="trackcom" pos="0 -3 0.3" xyaxes="1 0 0 0 0 1"/>
      <geom pos="0 0 0" size="0.25" type="sphere"/>
      <freejoint name="root"/>
      <body name="1" pos="0 0 0">
        <joint axis="-0.707107 0.707107 0" name="1_joint" pos="0 0 0" range="-30 30" type="hinge"/>
        <geom fromto="0 0 0 0.399962 0.399979 0" size="0.08001" type="capsule"/>
      </body>
      <body name="2" pos="0 0 0">
        <joint axis="-0.707107 -0.707107 0" name="2_joint" pos="0 0 0" range="-30 30" type="hinge"/>
        <geom fromto="0 0 0 -0.400006 0.399926 0" size="0.08" type="capsule"/>
        <body name="12" pos="-0.400006 0.399926 0">
          <joint axis="-0.707107 -0.707107 0" name="12_joint" pos="0 0 0" range="-30 30" type="hinge"/>
          <geom fromto="0 0 0 -0.399927 0.399964 0" size="0.080002" type="capsule"/>
        </body>
        <body name="22" pos="-0.400006 0.399926 0">
          <joint axis="-0.707107 -0.707107 0" name="22_joint" pos="0 0 0" range="-30 30" type="hinge"/>
          <geom fromto="0 0 0 -0.399983 0.4 0" size="0.079999" type="capsule"/>
          <body name="122" pos="-0.399983 0.4 0">
            <joint axis="-0.707107 -0.707107 0" name="122_joint" pos="0 0 0" range="-30 30" type="hinge"/>
            <geom fromto="0 0 0 -0.399957 0.400015 0" size="0.080001" type="capsule"/>
          </body>
          <body name="222" pos="-0.399983 0.4 0">
            <joint axis="-0.707107 -0.707107 0" name="222_joint" pos="0 0 0" range="-30 30" type="hinge"/>
            <geom fromto="0 0 0 -0.399995 0.400021 0" size="0.07999" type="capsule"/>
          </body>
        </body>
      </body>
      <body name="3" pos="0 0 0">
        <joint axis="0.707107 -0.707107 0" name="3_joint" pos="0 0 0" range="-30 30" type="hinge"/>
        <geom fromto="0 0 0 -0.400057 -0.400022 0" size="0.080003" type="capsule"/>
        <body name="13" pos="-0.400057 -0.400022 0">
          <joint axis="0.707107 -0.707107 0" name="13_joint" pos="0 0 0" range="-30 30" type="hinge"/>
          <geom fromto="0 0 0 -0.400077 -0.399903 0" size="0.079987" type="capsule"/>
          <body name="113" pos="-0.400077 -0.399903 0">
            <joint axis="0.707107 -0.707107 0" name="113_joint" pos="0 0 0" range="-30 30" type="hinge"/>
            <geom fromto="0 0 0 -0.399871 -0.399994 0" size="0.079999" type="capsule"/>
          </body>
          <body name="213" pos="-0.400077 -0.399903 0">
            <joint axis="0.707107 -0.707107 0" name="213_joint" pos="0 0 0" range="-30 30" type="hinge"/>
            <geom fromto="0 0 0 -0.400009 -0.399893 0" size="0.079993" type="capsule"/>
          </body>
        </body>
        <body name="23" pos="-0.400057 -0.400022 0">
          <joint axis="0.707107 -0.707107 0" name="23_joint" pos="0 0 0" range="-30 30" type="hinge"/>
          <geom fromto="0 0 0 -0.400077 -0.399962 0" size="0.080005" type="capsule"/>
        </body>
      </body>
      <body name="4" pos="0 0 0">
        <joint axis="0.707107 0.707107 0" name="4_joint" pos="0 0 0" range="-30 30" type="hinge"/>
        <geom fromto="0 0 0 0.399977 -0.400009 0" size="0.080005" type="capsule"/>
        <body name="14" pos="0.399977 -0.400009 0">
          <joint axis="0.707107 0.707107 0" name="14_joint" pos="0 0 0" range="-30 30" type="hinge"/>
          <geom fromto="0 0 0 0.399954 -0.400026 0" size="0.079996" type="capsule"/>
          <body name="114" pos="0.399954 -0.400026 0">
            <joint axis="0.707107 0.707107 0" name="114_joint" pos="0 0 0" range="-30 30" type="hinge"/>
            <geom fromto="-0 0 0 0.399968 -0.400014 0" size="0.079995" type="capsule"/>
          </body>
          <body name="214" pos="0.399954 -0.400026 0">
            <joint axis="0.707107 0.707107 0" name="214_joint" pos="0 0 0" range="-30 30" type="hinge"/>
            <geom fromto="-0 0 0 0.399948 -0.400066 0" size="0.080002" type="capsule"/>
          </body>
        </body>
        <body name="24" pos="0.399977 -0.400009 0">
          <joint axis="0.707107 0.707107 0" name="24_joint" pos="0 0 0" range="-30 30" type="hinge"/>
          <geom fromto="0 0 0 0.4 -0.400051 0" size="0.08" type="capsule"/>
        </body>
      </body>
    </body>
  </worldbody>
  <actuator>
    <motor ctrllimited="true" ctrlrange="-1.0 1.0" joint="1_joint" gear="150.001888" name="1_joint"/>
    <motor ctrllimited="true" ctrlrange="-1.0 1.0" joint="2_joint" gear="149.936674" name="2_joint"/>
    <motor ctrllimited="true" ctrlrange="-1.0 1.0" joint="3_joint" gear="149.998281" name="3_joint"/>
    <motor ctrllimited="true" ctrlrange="-1.0 1.0" joint="4_joint" gear="149.918752" name="4_joint"/>
    <motor ctrllimited="true" ctrlrange="-1.0 1.0" joint="12_joint" gear="149.982619" name="12_joint"/>
    <motor ctrllimited="true" ctrlrange="-1.0 1.0" joint="13_joint" gear="149.954697" name="13_joint"/>
    <motor ctrllimited="true" ctrlrange="-1.0 1.0" joint="14_joint" gear="149.994442" name="14_joint"/>
    <motor ctrllimited="true" ctrlrange="-1.0 1.0" joint="22_joint" gear="149.993292" name="22_joint"/>
    <motor ctrllimited="true" ctrlrange="-1.0 1.0" joint="23_joint" gear="150.060528" name="23_joint"/>
    <motor ctrllimited="true" ctrlrange="-1.0 1.0" joint="24_joint" gear="150.006565" name="24_joint"/>
    <motor ctrllimited="true" ctrlrange="-1.0 1.0" joint="113_joint" gear="149.955699" name="113_joint"/>
    <motor ctrllimited="true" ctrlrange="-1.0 1.0" joint="114_joint" gear="150.04986" name="114_joint"/>
    <motor ctrllimited="true" ctrlrange="-1.0 1.0" joint="213_joint" gear="150.013411" name="213_joint"/>
    <motor ctrllimited="true" ctrlrange="-1.0 1.0" joint="214_joint" gear="150.022845" name="214_joint"/>
    <motor ctrllimited="true" ctrlrange="-1.0 1.0" joint="122_joint" gear="150.036984" name="122_joint"/>
    <motor ctrllimited="true" ctrlrange="-1.0 1.0" joint="222_joint" gear="149.977245" name="222_joint"/>
  </actuator>
  <asset>
    <texture type="skybox" builtin="gradient" rgb1=".4 .5 .6" rgb2="0 0 0" width="100" height="100"/>
    <texture builtin="flat" height="1278" mark="cross" markrgb="1 1 1" name="texgeom" random="0.01" rgb1="0.8 0.6 0.4" rgb2="0.8 0.6 0.4" type="cube" width="127"/>
    <texture builtin="checker" height="100" name="texplane" rgb1="0 0 0" rgb2="0.8 0.8 0.8" type="2d" width="100"/>
    <material name="MatPlane" reflectance="0.5" shininess="1" specular="1" texrepeat="60 60" texture="texplane"/>
    <material name="geom" texture="texgeom" texuniform="true"/>
    <texture name="grid_new" type="2d" builtin="checker" rgb1=".1 .3 .2" rgb2=".2 .4 .3" width="1000" height="1000" mark="none" markrgb=".8 .6 .4"/>
    <material name="grid_new" texture="grid_new" texrepeat="0.2 0.2" texuniform="true" reflectance=".2"/>
  </asset>
</mujoco>
