<mujoco model="ant">
  <compiler inertiafromgeom="true" angle="degree"/>
  <option timestep="0.016" iterations="50" tolerance="1e-10" solver="Newton" jacobian="dense" cone="pyramidal"/>
  <default>
    <joint armature="1" damping="0.1" limited="true"/>
    <geom condim="3" density="5.0" friction="1.5 0.1 0.1" margin="0.01" rgba=".98 .54 .56 1."/>
  </default>
  <visual>
    <headlight ambient=".1 .1 .1" diffuse=".6 .6 .6" specular="0.3 0.3 0.3"/>
    <map znear=".01"/>
    <quality shadowsize="16384"/>
  </visual>
  <worldbody>
    <light cutoff="100" diffuse="1 1 1" dir="-0 0 -1.3" directional="true" exponent="1" pos="0 0 1.3" specular=".1 .1 .1"/>
    <geom condim="3" name="floor" pos="0 0 0" rgba="0.8 0.9 0.8 1" size="200 200 .125" type="plane" material="grid_new"/>
    <body name="0" pos="0 0 0">
      <camera name="track" mode="trackcom" pos="0 -3 0.3" xyaxes="1 0 0 0 0 1"/>
      <geom pos="0 0 0" size="0.25" type="sphere"/>
      <freejoint name="root"/>
      <body name="1" pos="0 0 0">
        <joint axis="-0.707107 0.707107 0" name="1_joint" pos="0 0 0" range="-30 30" type="hinge"/>
        <geom fromto="0 0 0 0.400062 0.3999 0" size="0.080017" type="capsule"/>
        <body name="11" pos="0.400062 0.3999 0">
          <joint axis="-0.707107 0.707107 0" name="11_joint" pos="0 0 0" range="-30 30" type="hinge"/>
          <geom fromto="0 0 0 0.399953 0.400021 0" size="0.079988" type="capsule"/>
        </body>
        <body name="21" pos="0.400062 0.3999 0">
          <joint axis="-0.707107 0.707107 0" name="21_joint" pos="0 0 0" range="-30 30" type="hinge"/>
          <geom fromto="-0 -0 0 0.400089 0.400027 0" size="0.079994" type="capsule"/>
        </body>
      </body>
      <body name="2" pos="0 0 0">
        <joint axis="-0.707107 -0.707107 0" name="2_joint" pos="0 0 0" range="-30 30" type="hinge"/>
        <geom fromto="0 -0 0 -0.399981 0.399868 0" size="0.080009" type="capsule"/>
      </body>
      <body name="3" pos="0 0 0">
        <joint axis="0.707107 -0.707107 0" name="3_joint" pos="0 0 0" range="-30 30" type="hinge"/>
        <geom fromto="0 0 0 -0.400164 -0.400107 0" size="0.080011" type="capsule"/>
      </body>
      <body name="4" pos="0 0 0">
        <joint axis="0.707107 0.707107 0" name="4_joint" pos="0 0 0" range="-30 30" type="hinge"/>
        <geom fromto="0 0 0 0.400047 -0.399943 0" size="0.079997" type="capsule"/>
      </body>
    </body>
  </worldbody>
  <actuator>
    <motor ctrllimited="true" ctrlrange="-1.0 1.0" joint="1_joint" gear="149.951045" name="1_joint"/>
    <motor ctrllimited="true" ctrlrange="-1.0 1.0" joint="2_joint" gear="149.884704" name="2_joint"/>
    <motor ctrllimited="true" ctrlrange="-1.0 1.0" joint="3_joint" gear="149.946039" name="3_joint"/>
    <motor ctrllimited="true" ctrlrange="-1.0 1.0" joint="4_joint" gear="149.875904" name="4_joint"/>
    <motor ctrllimited="true" ctrlrange="-1.0 1.0" joint="11_joint" gear="150.019929" name="11_joint"/>
    <motor ctrllimited="true" ctrlrange="-1.0 1.0" joint="21_joint" gear="149.965461" name="21_joint"/>
  </actuator>
  <asset>
    <texture type="skybox" builtin="gradient" rgb1=".4 .5 .6" rgb2="0 0 0" width="100" height="100"/>
    <texture builtin="flat" height="1278" mark="cross" markrgb="1 1 1" name="texgeom" random="0.01" rgb1="0.8 0.6 0.4" rgb2="0.8 0.6 0.4" type="cube" width="127"/>
    <texture builtin="checker" height="100" name="texplane" rgb1="0 0 0" rgb2="0.8 0.8 0.8" type="2d" width="100"/>
    <material name="MatPlane" reflectance="0.5" shininess="1" specular="1" texrepeat="60 60" texture="texplane"/>
    <material name="geom" texture="texgeom" texuniform="true"/>
    <texture name="grid_new" type="2d" builtin="checker" rgb1=".1 .3 .2" rgb2=".2 .4 .3" width="1000" height="1000" mark="none" markrgb=".8 .6 .4"/>
    <material name="grid_new" texture="grid_new" texrepeat="0.2 0.2" texuniform="true" reflectance=".2"/>
  </asset>
</mujoco>
