<mujoco model="mutiagent_world">
  <compiler angle="degree" coordinate="local" inertiafromgeom="true" />
  
  <option integrator="RK4" timestep="0.003" solver="PGS" iterations="1000" />
  
  <default>
    <joint armature="1" damping="1" limited="true" />
  <default class="agent0"><joint armature="1" damping="1" limited="true" />
    <geom conaffinity="1" contype="0" condim="3" density="5.0" friction="1 0.5 0.5" margin="0.01" rgba="0.5 0.25 0.25 1" />
  </default><default class="agent1"><joint armature="1" damping="1" limited="true" />
    <geom conaffinity="1" contype="1" condim="3" density="5.0" friction="1 0.5 0.5" margin="0.01" rgba="0.25 0.5 0.5 1" />
  </default></default>

  <asset>
    <texture builtin="gradient" height="100" rgb1="1 1 1" rgb2="0 0 0" type="skybox" width="100" />
    <texture builtin="flat" height="1278" mark="cross" markrgb="1 1 1" name="texgeom" random="0.01" rgb1=".1 .1 .1" rgb2=".3 .3 0.3" type="cube" width="127" />
    <texture builtin="checker" height="100" name="texplane" rgb1=".1 .1 .1" rgb2=".3 .3 0.3" type="2d" width="100" />
    <material name="MatPlane" reflectance="0.5" shininess="1" specular="1" texrepeat="60 60" texture="texplane" />
    <material name="geom" texture="texgeom" texuniform="true" />
  </asset>

  <worldbody>
    <light cutoff="100" diffuse="1 1 1" dir="-0 0 -1.3" directional="true" exponent="1" pos="0 0 1.3" specular=".1 .1 .1" />
    <geom contype="3" conaffinity="1" friction="1 .1 .1" condim="3" material="MatPlane" name="floor" pos="0 0 0" rgba="0.8 0.9 0.8 1" size="20 20 0.125" type="plane" />
    <geom fromto="4 -5 0  4 +5 0" name="rightgoal" rgba="0.6 0.0 0.0 1" size=".03" type="cylinder" />
    <geom fromto="-4 -5 0  -4 +5 0" name="leftgoal" rgba="0.6 0.0 0.0 1" size=".03" type="cylinder" />
  <body name="agent0/0" pos="-1 0 0.75" euler="0 0 0">
    <geom pos="0 0 0" size="0.25" type="sphere" class="agent0" name="agent0/anon9503618855" />
    <joint armature="0" damping="0" limited="false" margin="0.01" name="agent0/0_joint" pos="0 0 0" range="-30 30" type="free" />
    <body name="agent0/1" pos="0 0 0">
      <geom fromto="-0.002147 -0.001758 0 0.429706 0.351814 0" size="0.078592" type="capsule" class="agent0" name="agent0/anon4613904843" />
      <joint axis="-0.707107 0.707107 0" name="agent0/1_joint" pos="0 0 0" range="-30 30" type="hinge" />
    </body>
    <body name="agent0/2" pos="0 0 0">
      <geom fromto="0.00078 -0.001112 0 -0.309658 0.441551 0" size="0.077477" type="capsule" class="agent0" name="agent0/anon4704789831" />
      <joint axis="-0.707107 -0.707107 0" name="agent0/2_joint" pos="0 0 0" range="-30 30" type="hinge" />
      <body name="agent0/12" pos="-0.309658 0.441551 0">
        <geom fromto="0.000129 -0.000143 0 -0.359277 0.398246 0" size="0.088424" type="capsule" class="agent0" name="agent0/anon4991634663" />
        <joint axis="-0.707107 -0.707107 0" name="agent0/12_joint" pos="0 0 0" range="-30 30" type="hinge" />
      </body>
    </body>
    <body name="agent0/3" pos="0 0 0">
      <geom fromto="0.000146 0.00015 0 -0.384291 -0.393381 0" size="0.078467" type="capsule" class="agent0" name="agent0/anon1530999857" />
      <joint axis="0.707107 -0.707107 0" name="agent0/3_joint" pos="0 0 0" range="-30 30" type="hinge" />
      <body name="agent0/13" pos="-0.384291 -0.393381 0">
        <geom fromto="0.000125 0.000159 0 -0.362493 -0.460744 0" size="0.080727" type="capsule" class="agent0" name="agent0/anon8999278527" />
        <joint axis="0.707107 -0.707107 0" name="agent0/13_joint" pos="0 0 0" range="-30 30" type="hinge" />
        <body name="agent0/113" pos="-0.362493 -0.460744 0">
          <geom fromto="0.000054 0.000053 0 -0.427752 -0.425733 0" size="0.08462" type="capsule" class="agent0" name="agent0/anon615309930" />
          <joint axis="0.707107 -0.707107 0" name="agent0/113_joint" pos="0 0 0" range="-30 30" type="hinge" />
        </body>
      </body>
      <body name="agent0/23" pos="-0.384291 -0.393381 0">
        <geom fromto="0.000287 0.00034 0 -0.39096 -0.463689 0" size="0.078705" type="capsule" class="agent0" name="agent0/anon3606248724" />
        <joint axis="0.707107 -0.707107 0" name="agent0/23_joint" pos="0 0 0" range="-30 30" type="hinge" />
      </body>
    </body>
    <body name="agent0/4" pos="0 0 0">
      <geom fromto="-0.000038 0.000025 0 0.328405 -0.214497 0" size="0.080407" type="capsule" class="agent0" name="agent0/anon6971986545" />
      <joint axis="0.707107 0.707107 0" name="agent0/4_joint" pos="0 0 0" range="-30 30" type="hinge" />
      <body name="agent0/14" pos="0.328405 -0.214497 0">
        <geom fromto="-0.000389 0.000403 0 0.354176 -0.3671 0" size="0.086366" type="capsule" class="agent0" name="agent0/anon1393792052" />
        <joint axis="0.707107 0.707107 0" name="agent0/14_joint" pos="0 0 0" range="-30 30" type="hinge" />
      </body>
      <body name="agent0/24" pos="0.328405 -0.214497 0">
        <geom fromto="-0.000342 0.000308 0 0.473796 -0.426897 0" size="0.08174" type="capsule" class="agent0" name="agent0/anon3129130193" />
        <joint axis="0.707107 0.707107 0" name="agent0/24_joint" pos="0 0 0" range="-30 30" type="hinge" />
        <body name="agent0/124" pos="0.473796 -0.426897 0">
          <geom fromto="-0.000061 0.000066 0 0.428873 -0.460622 0" size="0.075041" type="capsule" class="agent0" name="agent0/anon3973704207" />
          <joint axis="0.707107 0.707107 0" name="agent0/124_joint" pos="0 0 0" range="-30 30" type="hinge" />
        </body>
        <body name="agent0/224" pos="0.473796 -0.426897 0">
          <geom fromto="-0 0 0 0.348984 -0.403041 0" size="0.083576" type="capsule" class="agent0" name="agent0/anon5169037456" />
          <joint axis="0.707107 0.707107 0" name="agent0/224_joint" pos="0 0 0" range="-30 30" type="hinge" />
        </body>
      </body>
    </body>
  </body>
  <body name="agent1/0" pos="1 0 0.75" euler="0 0 180">
    <geom pos="0 0 0" size="0.25" type="sphere" class="agent1" name="agent1/anon4329338678" />
    <joint armature="0" damping="0" limited="false" margin="0.01" name="agent1/0_joint" pos="0 0 0" range="-30 30" type="free" />
    <body name="agent1/1" pos="0 0 0">
      <geom fromto="-0.000485 -0.000382 0 0.370862 0.291806 0" size="0.07592" type="capsule" class="agent1" name="agent1/anon3978646010" />
      <joint axis="-0.707107 0.707107 0" name="agent1/1_joint" pos="0 0 0" range="-30 30" type="hinge" />
      <body name="agent1/11" pos="0.370862 0.291806 0">
        <geom fromto="-0.000394 -0.00036 0 0.394369 0.361018 0" size="0.081958" type="capsule" class="agent1" name="agent1/anon9854852054" />
        <joint axis="-0.707107 0.707107 0" name="agent1/11_joint" pos="0 0 0" range="-30 30" type="hinge" />
        <body name="agent1/111" pos="0.394369 0.361018 0">
          <geom fromto="-0.001855 -0.002052 0 0.399438 0.441808 0" size="0.082079" type="capsule" class="agent1" name="agent1/anon9306986223" />
          <joint axis="-0.707107 0.707107 0" name="agent1/111_joint" pos="0 0 0" range="-30 30" type="hinge" />
        </body>
      </body>
    </body>
    <body name="agent1/2" pos="0 0 0">
      <geom fromto="0.000144 -0.000127 0 -0.427344 0.37703 0" size="0.08998" type="capsule" class="agent1" name="agent1/anon4398482989" />
      <joint axis="-0.707107 -0.707107 0" name="agent1/2_joint" pos="0 0 0" range="-30 30" type="hinge" />
      <body name="agent1/12" pos="-0.427344 0.37703 0">
        <geom fromto="0.001155 -0.001053 0 -0.418063 0.381061 0" size="0.081991" type="capsule" class="agent1" name="agent1/anon6236299415" />
        <joint axis="-0.707107 -0.707107 0" name="agent1/12_joint" pos="0 0 0" range="-30 30" type="hinge" />
        <body name="agent1/112" pos="-0.418063 0.381061 0">
          <geom fromto="0.000106 -0.000112 0 -0.392173 0.415259 0" size="0.088813" type="capsule" class="agent1" name="agent1/anon1582166541" />
          <joint axis="-0.707107 -0.707107 0" name="agent1/112_joint" pos="0 0 0" range="-30 30" type="hinge" />
        </body>
      </body>
    </body>
    <body name="agent1/3" pos="0 0 0">
      <geom fromto="0.000034 0.000043 0 -0.344002 -0.428689 0" size="0.086496" type="capsule" class="agent1" name="agent1/anon2616524092" />
      <joint axis="0.707107 -0.707107 0" name="agent1/3_joint" pos="0 0 0" range="-30 30" type="hinge" />
      <body name="agent1/13" pos="-0.344002 -0.428689 0">
        <geom fromto="0.000001 0.000001 0 -0.464479 -0.394099 0" size="0.089237" type="capsule" class="agent1" name="agent1/anon8739604429" />
        <joint axis="0.707107 -0.707107 0" name="agent1/13_joint" pos="0 0 0" range="-30 30" type="hinge" />
        <body name="agent1/113" pos="-0.464479 -0.394099 0">
          <geom fromto="0.00015 0.000163 0 -0.419449 -0.456792 0" size="0.077221" type="capsule" class="agent1" name="agent1/anon8644535079" />
          <joint axis="0.707107 -0.707107 0" name="agent1/113_joint" pos="0 0 0" range="-30 30" type="hinge" />
        </body>
      </body>
      <body name="agent1/23" pos="-0.344002 -0.428689 0">
        <geom fromto="0.000082 0.000095 0 -0.36244 -0.419496 0" size="0.080322" type="capsule" class="agent1" name="agent1/anon8423793478" />
        <joint axis="0.707107 -0.707107 0" name="agent1/23_joint" pos="0 0 0" range="-30 30" type="hinge" />
      </body>
    </body>
    <body name="agent1/4" pos="0 0 0">
      <geom fromto="-0.003433 0.00294 0 0.432242 -0.370177 0" size="0.085507" type="capsule" class="agent1" name="agent1/anon452651974" />
      <joint axis="0.707107 0.707107 0" name="agent1/4_joint" pos="0 0 0" range="-30 30" type="hinge" />
    </body>
  </body>
  </worldbody>
<actuator>
    <motor ctrllimited="true" ctrlrange="-1.0 1.0" joint="agent0/1_joint" gear="196.754177" name="agent0/1_joint" class="agent0" />
    <motor ctrllimited="true" ctrlrange="-1.0 1.0" joint="agent0/2_joint" gear="145.396809" name="agent0/2_joint" class="agent0" />
    <motor ctrllimited="true" ctrlrange="-1.0 1.0" joint="agent0/3_joint" gear="182.998086" name="agent0/3_joint" class="agent0" />
    <motor ctrllimited="true" ctrlrange="-1.0 1.0" joint="agent0/4_joint" gear="108.928582" name="agent0/4_joint" class="agent0" />
    <motor ctrllimited="true" ctrlrange="-1.0 1.0" joint="agent0/14_joint" gear="194.172133" name="agent0/14_joint" class="agent0" />
    <motor ctrllimited="true" ctrlrange="-1.0 1.0" joint="agent0/24_joint" gear="161.185263" name="agent0/24_joint" class="agent0" />
    <motor ctrllimited="true" ctrlrange="-1.0 1.0" joint="agent0/12_joint" gear="164.603878" name="agent0/12_joint" class="agent0" />
    <motor ctrllimited="true" ctrlrange="-1.0 1.0" joint="agent0/13_joint" gear="157.396797" name="agent0/13_joint" class="agent0" />
    <motor ctrllimited="true" ctrlrange="-1.0 1.0" joint="agent0/124_joint" gear="199.345453" name="agent0/124_joint" class="agent0" />
    <motor ctrllimited="true" ctrlrange="-1.0 1.0" joint="agent0/23_joint" gear="94.057187" name="agent0/23_joint" class="agent0" />
    <motor ctrllimited="true" ctrlrange="-1.0 1.0" joint="agent0/224_joint" gear="157.702721" name="agent0/224_joint" class="agent0" />
    <motor ctrllimited="true" ctrlrange="-1.0 1.0" joint="agent0/113_joint" gear="93.125742" name="agent0/113_joint" class="agent0" />
  <motor ctrllimited="true" ctrlrange="-1.0 1.0" joint="agent1/1_joint" gear="150.040654" name="agent1/1_joint" class="agent1" />
    <motor ctrllimited="true" ctrlrange="-1.0 1.0" joint="agent1/2_joint" gear="141.009785" name="agent1/2_joint" class="agent1" />
    <motor ctrllimited="true" ctrlrange="-1.0 1.0" joint="agent1/3_joint" gear="137.680079" name="agent1/3_joint" class="agent1" />
    <motor ctrllimited="true" ctrlrange="-1.0 1.0" joint="agent1/4_joint" gear="137.738748" name="agent1/4_joint" class="agent1" />
    <motor ctrllimited="true" ctrlrange="-1.0 1.0" joint="agent1/13_joint" gear="141.414987" name="agent1/13_joint" class="agent1" />
    <motor ctrllimited="true" ctrlrange="-1.0 1.0" joint="agent1/12_joint" gear="153.493705" name="agent1/12_joint" class="agent1" />
    <motor ctrllimited="true" ctrlrange="-1.0 1.0" joint="agent1/11_joint" gear="152.62972" name="agent1/11_joint" class="agent1" />
    <motor ctrllimited="true" ctrlrange="-1.0 1.0" joint="agent1/23_joint" gear="142.867626" name="agent1/23_joint" class="agent1" />
    <motor ctrllimited="true" ctrlrange="-1.0 1.0" joint="agent1/113_joint" gear="124.430554" name="agent1/113_joint" class="agent1" />
    <motor ctrllimited="true" ctrlrange="-1.0 1.0" joint="agent1/112_joint" gear="117.415954" name="agent1/112_joint" class="agent1" />
    <motor ctrllimited="true" ctrlrange="-1.0 1.0" joint="agent1/111_joint" gear="161.605527" name="agent1/111_joint" class="agent1" />
  </actuator>
  </mujoco>