<mujoco model="mutiagent_world">
  <compiler angle="degree" coordinate="local" inertiafromgeom="true" />
  
  <option integrator="RK4" timestep="0.003" solver="PGS" iterations="1000" />
  
  <default>
    <joint armature="1" damping="1" limited="true" />
  <default class="agent0"><joint armature="1" damping="1" limited="true" />
    <geom conaffinity="0" condim="3" density="5.0" friction="1 0.5 0.5" margin="0.01" rgba="0.98 0.54 0.56 1" material="geom" contype="1" /> 
    <!-- <geom conaffinity="0" condim="3" density="5.0" friction="1 0.5 0.5" margin="0.01" rgba="0.11 0.56 1 1" material="geom" contype="1" />  -->
  </default></default>

  <visual>
    <headlight ambient=".1 .1 .1" diffuse=".6 .6 .6" specular="0.3 0.3 0.3" />
    <map znear=".01" />
    <quality shadowsize="16384" />
  </visual>

  <asset>
    <texture builtin="gradient" height="100" rgb1=".4 .5 .6" rgb2="0 0 0" type="skybox" width="100" />
    <texture builtin="flat" height="1278" mark="cross" markrgb="0 0 0" name="texgeom" random="0.01" rgb1="0.8 0.6 0.4" rgb2="1 1 1" type="cube" width="127" />
    <texture builtin="checker" height="100" name="texplane" rgb1="0 0 0" rgb2="0.8 0.8 0.8" type="2d" width="100" />
    <material name="geom" texture="texgeom" texuniform="true" />
    <texture name="MatPlane" type="2d" builtin="checker" rgb1=".4 .4 .4" rgb2=".4 .4 .4" width="300" height="300" mark="edge" markrgb="0.1 0.1 0.1" />
    <material name="MatPlane" texture="MatPlane" texrepeat="2 2" texuniform="true" reflectance=".2" />
  </asset>

  <worldbody>
    <light cutoff="100" diffuse="1 1 1" dir="-0 0 -1.3" directional="true" exponent="1" pos="0 0 1.3" specular=".1 .1 .1" />
    <geom contype="1" conaffinity="1" friction="1 .1 .1" condim="3" material="MatPlane" name="floor" pos="0 0 0" rgba="0.8 0.9 0.8 1" size="20 20 0.125" type="plane" />
    <geom fromto="4 -5 0  4 +5 0" name="rightgoal" rgba="1 0 0 0.5" size=".03" type="cylinder" />
    <geom fromto="-4 -5 0  -4 +5 0" name="leftgoal" rgba="1 0 0 0.5" size=".03" type="cylinder" />
  <body name="agent0/0" pos="-1 0 0.75" euler="0 0 0">
    <geom pos="0 0 0" size="0.25" type="sphere" class="agent0" name="agent0/anon9747051754" />
    <joint armature="0" damping="0" limited="false" margin="0.01" name="agent0/0_joint" pos="0 0 0" range="-30 30" type="free" />
    <body name="agent0/1" pos="0 0 0">
      <geom fromto="-0.001547 -0.001551 0 0.397442 0.398246 0" size="0.077456" type="capsule" class="agent0" name="agent0/anon9312739131" />
      <joint axis="0 0 1" name="agent0/1_joint" pos="0 0 0" range="-30 30" type="hinge" />
      <body name="agent0/11" pos="0.397442 0.398246 0">
        <geom fromto="-0.000002 -0.000002 0 0.399937 0.390403 0" size="0.080875" type="capsule" class="agent0" name="agent0/anon5234552480" />
        <joint axis="-0.707107 0.707107 0" name="agent0/11_joint" pos="0 0 0" range="-60 60" type="hinge" />
      </body>
    </body>
    <body name="agent0/2" pos="0 0 0">
      <geom fromto="0.001967 -0.001976 0 -0.391967 0.393733 0" size="0.083505" type="capsule" class="agent0" name="agent0/anon1734463156" />
      <joint axis="0 0 1" name="agent0/2_joint" pos="0 0 0" range="-30 30" type="hinge" />
      <body name="agent0/12" pos="-0.391967 0.393733 0">
        <geom fromto="0.001029 -0.00101 0 -0.397982 0.390521 0" size="0.082691" type="capsule" class="agent0" name="agent0/anon278710078" />
        <joint axis="-0.707107 -0.707107 0" name="agent0/12_joint" pos="0 0 0" range="-60 60" type="hinge" />
        <body name="agent0/112" pos="-0.397982 0.390521 0">
          <geom fromto="0.000064 -0.000064 0 -0.399558 0.398953 0" size="0.078963" type="capsule" class="agent0" name="agent0/anon1090558394" />
          <joint axis="-0.707107 -0.707107 0" name="agent0/112_joint" pos="0 0 0" range="-60 60" type="hinge" />
        </body>
      </body>
    </body>
    <body name="agent0/3" pos="0 0 0">
      <geom fromto="0.002005 0.002005 0 -0.39923 -0.399198 0" size="0.08939" type="capsule" class="agent0" name="agent0/anon7285571367" />
      <joint axis="0 0 1" name="agent0/3_joint" pos="0 0 0" range="-30 30" type="hinge" />
      <body name="agent0/13" pos="-0.39923 -0.399198 0">
        <geom fromto="0.00135 0.001315 0 -0.398362 -0.387847 0" size="0.073169" type="capsule" class="agent0" name="agent0/anon7354146179" />
        <joint axis="0.707107 -0.707107 0" name="agent0/13_joint" pos="0 0 0" range="-60 60" type="hinge" />
        <body name="agent0/113" pos="-0.398362 -0.387847 0">
          <geom fromto="0.000253 0.000267 0 -0.374924 -0.396313 0" size="0.087034" type="capsule" class="agent0" name="agent0/anon636028517" />
          <joint axis="0.707107 -0.707107 0" name="agent0/113_joint" pos="0 0 0" range="-60 60" type="hinge" />
        </body>
      </body>
    </body>
    <body name="agent0/4" pos="0 0 0">
      <geom fromto="-0.00001 0.00001 0 0.399714 -0.399997 0" size="0.073856" type="capsule" class="agent0" name="agent0/anon4285262776" />
      <joint axis="0 0 1" name="agent0/4_joint" pos="0 0 0" range="-30 30" type="hinge" />
      <body name="agent0/14" pos="0.399714 -0.399997 0">
        <geom fromto="-0.000249 0.000247 0 0.399661 -0.397353 0" size="0.081519" type="capsule" class="agent0" name="agent0/anon1145815739" />
        <joint axis="0.707107 0.707107 0" name="agent0/14_joint" pos="0 0 0" range="-60 60" type="hinge" />
      </body>
      <body name="agent0/24" pos="0.399714 -0.399997 0">
        <geom fromto="-0.000764 0.000753 0 0.398609 -0.392628 0" size="0.085445" type="capsule" class="agent0" name="agent0/anon4194529282" />
        <joint axis="0 0 1" name="agent0/24_joint" pos="0 0 0" range="-30 30" type="hinge" />
      </body>
    </body>
  </body>
  </worldbody>
<actuator>
    <motor ctrllimited="true" ctrlrange="-1.0 1.0" joint="agent0/1_joint" gear="136.531975" name="agent0/1_joint" class="agent0" />
    <motor ctrllimited="true" ctrlrange="-1.0 1.0" joint="agent0/2_joint" gear="150.327671" name="agent0/2_joint" class="agent0" />
    <motor ctrllimited="true" ctrlrange="-1.0 1.0" joint="agent0/3_joint" gear="117.660937" name="agent0/3_joint" class="agent0" />
    <motor ctrllimited="true" ctrlrange="-1.0 1.0" joint="agent0/4_joint" gear="160.560086" name="agent0/4_joint" class="agent0" />
    <motor ctrllimited="true" ctrlrange="-1.0 1.0" joint="agent0/11_joint" gear="117.727597" name="agent0/11_joint" class="agent0" />
    <motor ctrllimited="true" ctrlrange="-1.0 1.0" joint="agent0/12_joint" gear="202.518387" name="agent0/12_joint" class="agent0" />
    <motor ctrllimited="true" ctrlrange="-1.0 1.0" joint="agent0/13_joint" gear="113.551376" name="agent0/13_joint" class="agent0" />
    <motor ctrllimited="true" ctrlrange="-1.0 1.0" joint="agent0/14_joint" gear="140.486754" name="agent0/14_joint" class="agent0" />
    <motor ctrllimited="true" ctrlrange="-1.0 1.0" joint="agent0/112_joint" gear="127.028536" name="agent0/112_joint" class="agent0" />
    <motor ctrllimited="true" ctrlrange="-1.0 1.0" joint="agent0/113_joint" gear="150.619407" name="agent0/113_joint" class="agent0" />
    <motor ctrllimited="true" ctrlrange="-1.0 1.0" joint="agent0/24_joint" gear="168.462531" name="agent0/24_joint" class="agent0" />
  </actuator>
  </mujoco>