<mujoco model="mutiagent_world">
  <compiler angle="degree" coordinate="local" inertiafromgeom="true" />
  
  <option integrator="RK4" timestep="0.003" solver="PGS" iterations="1000" />
  
  <default>
    <joint armature="1" damping="1" limited="true" />
  <default class="agent0"><joint armature="1" damping="1" limited="true" />
    <geom conaffinity="0" condim="3" density="5.0" friction="1 0.5 0.5" margin="0.01" rgba="0.5 0.25 0.25 1" contype="1" />
  </default></default>

  <asset>
    <texture builtin="gradient" height="100" rgb1="1 1 1" rgb2="0 0 0" type="skybox" width="100" />
    <texture builtin="flat" height="1278" mark="cross" markrgb="1 1 1" name="texgeom" random="0.01" rgb1=".1 .1 .1" rgb2=".3 .3 0.3" type="cube" width="127" />
    <texture builtin="checker" height="100" name="texplane" rgb1=".1 .1 .1" rgb2=".3 .3 0.3" type="2d" width="100" />
    <material name="MatPlane" reflectance="0.5" shininess="1" specular="1" texrepeat="60 60" texture="texplane" />
    <material name="geom" texture="texgeom" texuniform="true" />
  </asset>

  <worldbody>
    <light cutoff="100" diffuse="1 1 1" dir="-0 0 -1.3" directional="true" exponent="1" pos="0 0 1.3" specular=".1 .1 .1" />
    <geom contype="1" conaffinity="1" friction="1 .1 .1" condim="3" material="MatPlane" name="floor" pos="0 0 0" rgba="0.8 0.9 0.8 1" size="20 20 0.125" type="plane" />
    <geom fromto="4 -5 0  4 +5 0" name="rightgoal" rgba="0.6 0.0 0.0 1" size=".03" type="cylinder" />
    <geom fromto="-4 -5 0  -4 +5 0" name="leftgoal" rgba="0.6 0.0 0.0 1" size=".03" type="cylinder" />
  <body name="agent0/0" pos="-1 0 0.75" euler="0 0 0">
      <geom pos="0 0 0" size="0.25" type="sphere" class="agent0" name="agent0/anon8577843436" />
      <joint armature="0" damping="0" limited="false" margin="0.01" name="agent0/root" pos="0 0 0" range="-30 30" type="free" />
      <body name="agent0/1" pos="0 0 0">
          <geom fromto="0.0 0.0 0.0 0.4 0.4 0.0" size="0.08" type="capsule" class="agent0" name="agent0/anon4005303369" />
          <joint axis="-1 1 0" name="agent0/1_joint" pos="0.0 0.0 0.0" range="-30 30" type="hinge" />
      </body>
      <body name="agent0/2" pos="0 0 0">
          <geom fromto="0.0 0.0 0.0 -0.4 0.4 0.0" size="0.08" type="capsule" class="agent0" name="agent0/anon1703301250" />
          <joint axis="-1 -1 0" name="agent0/2_joint" pos="0.0 0.0 0.0" range="-30 30" type="hinge" />
      </body>
      <body name="agent0/3" pos="0 0 0">
          <geom fromto="0.0 0.0 0.0 -0.4 -0.4 0.0" size="0.08" type="capsule" class="agent0" name="agent0/anon1666063944" />
          <joint axis="1 -1 0" name="agent0/3_joint" pos="0.0 0.0 0.0" range="-30 30" type="hinge" />
      </body>
      <body name="agent0/4" pos="0 0 0">
          <geom fromto="0.0 0.0 0.0 0.4 -0.4 0.0" size="0.08" type="capsule" class="agent0" name="agent0/anon7171504637" />
          <joint axis="1 1 0" name="agent0/4_joint" pos="0.0 0.0 0.0" range="-30 30" type="hinge" />
      </body>
    </body>

  </worldbody>
<actuator>
    <motor ctrllimited="true" ctrlrange="-1.0 1.0" joint="agent0/1_joint" gear="150" name="agent0/1_joint" class="agent0" />
    <motor ctrllimited="true" ctrlrange="-1.0 1.0" joint="agent0/2_joint" gear="150" name="agent0/2_joint" class="agent0" />
    <motor ctrllimited="true" ctrlrange="-1.0 1.0" joint="agent0/3_joint" gear="150" name="agent0/3_joint" class="agent0" />
    <motor ctrllimited="true" ctrlrange="-1.0 1.0" joint="agent0/4_joint" gear="150" name="agent0/4_joint" class="agent0" />
  </actuator>
  </mujoco>