<mujoco model="mutiagent_world">
  <compiler angle="degree" coordinate="local" inertiafromgeom="true" />
  
  <option integrator="RK4" timestep="0.003" solver="PGS" iterations="1000" />
  
  <default>
    <joint armature="1" damping="1" limited="true" />
  <default class="agent0"><joint armature="1" damping="1" limited="true" />
    <geom conaffinity="0" condim="3" density="5.0" friction="1 0.5 0.5" margin="0.01" rgba="0.98 0.87 0.67 1" material="geom" contype="1" />
  </default><default class="agent1"><joint armature="1" damping="1" limited="true" />
    <geom conaffinity="1" condim="3" density="5.0" friction="1 0.5 0.5" margin="0.01" rgba="0.98 0.87 0.67 1" material="geom" contype="0" />
  </default></default>

  <visual>
    <headlight ambient=".1 .1 .1" diffuse=".6 .6 .6" specular="0.3 0.3 0.3" />
    <map znear=".01" />
    <quality shadowsize="16384" />
  </visual>

  <asset>
    <texture builtin="gradient" height="100" rgb1=".4 .5 .6" rgb2="0 0 0" type="skybox" width="100" />
    <texture builtin="flat" height="1278" mark="cross" markrgb="0 0 0" name="texgeom" random="0.01" rgb1="0.8 0.6 0.4" rgb2="0.8 0.6 0.4" type="cube" width="127" />
    <texture builtin="checker" height="100" name="texplane" rgb1="0 0 0" rgb2="0.8 0.8 0.8" type="2d" width="100" />
    <texture name="MatPlane" type="2d" builtin="checker" rgb1=".5 .5 .5" rgb2=".5 .5 .5" width="300" height="300" mark="edge" markrgb="0.1 0.1 0.1" />
    <material name="MatPlane" texture="MatPlane" texrepeat="2 2" texuniform="true" reflectance=".2" />
    <material name="geom" texture="texgeom" texuniform="true" />
  </asset>

  <worldbody>
    <light cutoff="100" diffuse="1 1 1" dir="-0 0 -1.3" directional="true" exponent="1" pos="0 0 1.3" specular=".1 .1 .1" />
    <geom contype="1" conaffinity="1" friction="1 .1 .1" condim="3" material="MatPlane" name="floor" pos="0 0 0" rgba="1 1 1 1" size="20 20 0.125" type="plane" />
    <geom fromto="4 -5 0  4 +5 0" name="rightgoal" rgba="1 0 0 0.5" size=".03" type="cylinder" />
    <geom fromto="-4 -5 0  -4 +5 0" name="leftgoal" rgba="1 0 0 0.5" size=".03" type="cylinder" />
  <body name="agent0/0" pos="-1 0 0.75" euler="0 0 0">
      <geom pos="0 0 0" size="0.25" type="sphere" class="agent0" name="agent0/anon2355859551" />
      <joint armature="0" damping="0" limited="false" margin="0.01" name="agent0/root" pos="0 0 0" range="-30 30" type="free" />
      <body name="agent0/1" pos="0 0 0">
          <geom fromto="0.0 0.0 0.0 0.4 0.4 0.0" size="0.08" type="capsule" class="agent0" name="agent0/anon4052095259" />
          <joint axis="-1 1 0" name="agent0/1_joint" pos="0.0 0.0 0.0" range="-30 30" type="hinge" />
      </body>
      <body name="agent0/2" pos="0 0 0">
          <geom fromto="0.0 0.0 0.0 -0.4 0.4 0.0" size="0.08" type="capsule" class="agent0" name="agent0/anon4769990318" />
          <joint axis="-1 -1 0" name="agent0/2_joint" pos="0.0 0.0 0.0" range="-30 30" type="hinge" />
      </body>
      <body name="agent0/3" pos="0 0 0">
          <geom fromto="0.0 0.0 0.0 -0.4 -0.4 0.0" size="0.08" type="capsule" class="agent0" name="agent0/anon2075973529" />
          <joint axis="1 -1 0" name="agent0/3_joint" pos="0.0 0.0 0.0" range="-30 30" type="hinge" />
      </body>
      <body name="agent0/4" pos="0 0 0">
          <geom fromto="0.0 0.0 0.0 0.4 -0.4 0.0" size="0.08" type="capsule" class="agent0" name="agent0/anon3098734066" />
          <joint axis="1 1 0" name="agent0/4_joint" pos="0.0 0.0 0.0" range="-30 30" type="hinge" />
      </body>
    </body>
  

  <body name="agent1/0" pos="1 0 0.75" euler="0 0 180">
      <geom pos="0 0 0" size="0.25" type="sphere" class="agent1" name="agent1/anon4504857663" />
      <joint armature="0" damping="0" limited="false" margin="0.01" name="agent1/root" pos="0 0 0" range="-30 30" type="free" />
      <body name="agent1/1" pos="0 0 0">
          <geom fromto="0.0 0.0 0.0 0.4 0.4 0.0" size="0.08" type="capsule" class="agent1" name="agent1/anon5140083363" />
          <joint axis="-1 1 0" name="agent1/1_joint" pos="0.0 0.0 0.0" range="-30 30" type="hinge" />
      </body>
      <body name="agent1/2" pos="0 0 0">
          <geom fromto="0.0 0.0 0.0 -0.4 0.4 0.0" size="0.08" type="capsule" class="agent1" name="agent1/anon5031723857" />
          <joint axis="-1 -1 0" name="agent1/2_joint" pos="0.0 0.0 0.0" range="-30 30" type="hinge" />
      </body>
      <body name="agent1/3" pos="0 0 0">
          <geom fromto="0.0 0.0 0.0 -0.4 -0.4 0.0" size="0.08" type="capsule" class="agent1" name="agent1/anon1012869891" />
          <joint axis="1 -1 0" name="agent1/3_joint" pos="0.0 0.0 0.0" range="-30 30" type="hinge" />
      </body>
      <body name="agent1/4" pos="0 0 0">
          <geom fromto="0.0 0.0 0.0 0.4 -0.4 0.0" size="0.08" type="capsule" class="agent1" name="agent1/anon1612058358" />
          <joint axis="1 1 0" name="agent1/4_joint" pos="0.0 0.0 0.0" range="-30 30" type="hinge" />
      </body>
    </body>
  

  </worldbody>
<actuator>
    <motor ctrllimited="true" ctrlrange="-1.0 1.0" joint="agent0/1_joint" gear="150" name="agent0/1_joint" class="agent0" />
    <motor ctrllimited="true" ctrlrange="-1.0 1.0" joint="agent0/2_joint" gear="150" name="agent0/2_joint" class="agent0" />
    <motor ctrllimited="true" ctrlrange="-1.0 1.0" joint="agent0/3_joint" gear="150" name="agent0/3_joint" class="agent0" />
    <motor ctrllimited="true" ctrlrange="-1.0 1.0" joint="agent0/4_joint" gear="150" name="agent0/4_joint" class="agent0" />
  <motor ctrllimited="true" ctrlrange="-1.0 1.0" joint="agent1/1_joint" gear="150" name="agent1/1_joint" class="agent1" />
    <motor ctrllimited="true" ctrlrange="-1.0 1.0" joint="agent1/2_joint" gear="150" name="agent1/2_joint" class="agent1" />
    <motor ctrllimited="true" ctrlrange="-1.0 1.0" joint="agent1/3_joint" gear="150" name="agent1/3_joint" class="agent1" />
    <motor ctrllimited="true" ctrlrange="-1.0 1.0" joint="agent1/4_joint" gear="150" name="agent1/4_joint" class="agent1" />
  </actuator>
  </mujoco>