<mujoco model="mutiagent_world">
  <compiler angle="degree" coordinate="local" inertiafromgeom="true" />
  <option integrator="RK4" timestep="0.003" solver="PGS" iterations="1000" />
  <default>
    <joint armature="1" damping="1" limited="true" />
  <default class="agent0"><joint armature="1" damping="1" limited="true" />
    <geom conaffinity="0" condim="3" density="5.0" friction="1 0.5 0.5" margin="0.01" rgba="0.98 0.87 0.67 1" material="geom" contype="1" />
    <motor ctrllimited="true" ctrlrange="-.4 .4" />
</default><default class="agent1"><joint armature="1" damping="1" limited="true" />
    <geom conaffinity="1" condim="3" density="5.0" friction="1 0.5 0.5" margin="0.01" rgba="0.98 0.87 0.67 1" material="geom" contype="0" />
  </default></default>
  <visual>
    <headlight ambient=".1 .1 .1" diffuse=".6 .6 .6" specular="0.3 0.3 0.3" />
    <map znear=".01" />
    <quality shadowsize="16384" />
  </visual>
  <asset>
    <texture builtin="gradient" height="100" rgb1="1 1 1" rgb2="0 0 0" type="skybox" width="100" />
    <texture builtin="flat" height="1278" mark="cross" markrgb="1 1 1" name="texgeom" random="0.01" rgb1="0.8 0.6 0.4" rgb2="0.8 0.6 0.4" type="cube" width="127" />
    <texture builtin="checker" height="100" name="texplane" rgb1="0.1 0.1 0.1" rgb2="0.1 0.1 0.1" type="2d" width="100" markrgb="0.2 0.2 0.2" mark="edge" />
    <material name="MatPlane" reflectance="0.5" shininess="1" specular="1" texrepeat="60 60" texture="texplane" />
    <material name="geom" texture="texgeom" texuniform="true" />
  </asset>
  <worldbody>
    <light cutoff="100" diffuse="1 1 1" dir="-0 0 -1.3" directional="true" exponent="1" pos="0 0 1.3" specular=".1 .1 .1" />
    <geom contype="1" conaffinity="1" friction="1 .1 .1" condim="3" material="MatPlane" name="floor" pos="0 0 0" rgba="1 1 1 1" size="20 20 0.125" type="plane" />
    <geom fromto="4 -5 0  4 +5 0" name="rightgoal" rgba="0.6 0.0 0.0 0" size=".03" type="cylinder" />
    <geom fromto="-4 -5 0  -4 +5 0" name="leftgoal" rgba="0.6 0.0 0.0 0" size=".03" type="cylinder" />
    <geom conaffinity="1" condim="3" contype="1" friction="1 .1 .1" name="arena" size="4.5 .25" type="cylinder" pos="0 0 0.25" rgba="0.4 0.4 0.4 0.8" />
  <body name="agent0/torso" pos="-1 0 1.5" euler="0 0 0">
  <geom name="agent0/torso_geom" pos="0 0 0" size="0.25" type="sphere" class="agent0" />
  <joint armature="0" damping="0" limited="false" margin="0.01" name="agent0/root" pos="0 0 0" range="-30 30" type="free" />
  <body name="agent0/front_left_leg" pos="0 0 0">
    <geom fromto="0.0 0.0 0.0 0.2 0.2 0.0" name="agent0/aux_1_geom" size="0.08" type="capsule" class="agent0" />
    <body name="agent0/aux_1" pos="0.2 0.2 0">
      <joint axis="0 0 1" name="agent0/hip_1" pos="0.0 0.0 0.0" range="-30 30" type="hinge" />
      <geom fromto="0.0 0.0 0.0 0.2 0.2 0.0" name="agent0/left_leg_geom" size="0.08" type="capsule" class="agent0" />
      <body pos="0.2 0.2 0" name="agent0/anon4495394816">
        <joint axis="-1 1 0" name="agent0/ankle_1" pos="0.0 0.0 0.0" range="30 70" type="hinge" />
        <geom fromto="0.0 0.0 0.0 0.4 0.4 0.0" name="agent0/left_ankle_geom" size="0.08" type="capsule" class="agent0" />
      </body>
    </body>
  </body>
  <body name="agent0/front_right_leg" pos="0 0 0">
    <geom fromto="0.0 0.0 0.0 -0.2 0.2 0.0" name="agent0/aux_2_geom" size="0.08" type="capsule" class="agent0" />
    <body name="agent0/aux_2" pos="-0.2 0.2 0">
      <joint axis="0 0 1" name="agent0/hip_2" pos="0.0 0.0 0.0" range="-30 30" type="hinge" />
      <geom fromto="0.0 0.0 0.0 -0.2 0.2 0.0" name="agent0/right_leg_geom" size="0.08" type="capsule" class="agent0" />
      <body pos="-0.2 0.2 0" name="agent0/anon4684118974">
        <joint axis="1 1 0" name="agent0/ankle_2" pos="0.0 0.0 0.0" range="-70 -30" type="hinge" />
        <geom fromto="0.0 0.0 0.0 -0.4 0.4 0.0" name="agent0/right_ankle_geom" size="0.08" type="capsule" class="agent0" />
      </body>
    </body>
  </body>
  <body name="agent0/back_leg" pos="0 0 0">
    <geom fromto="0.0 0.0 0.0 -0.2 -0.2 0.0" name="agent0/aux_3_geom" size="0.08" type="capsule" class="agent0" />
    <body name="agent0/aux_3" pos="-0.2 -0.2 0">
      <joint axis="0 0 1" name="agent0/hip_3" pos="0.0 0.0 0.0" range="-30 30" type="hinge" />
      <geom fromto="0.0 0.0 0.0 -0.2 -0.2 0.0" name="agent0/back_leg_geom" size="0.08" type="capsule" class="agent0" />
      <body pos="-0.2 -0.2 0" name="agent0/anon1934879561">
        <joint axis="-1 1 0" name="agent0/ankle_3" pos="0.0 0.0 0.0" range="-70 -30" type="hinge" />
        <geom fromto="0.0 0.0 0.0 -0.4 -0.4 0.0" name="agent0/third_ankle_geom" size="0.08" type="capsule" class="agent0" />
      </body>
    </body>
  </body>
  <body name="agent0/right_back_leg" pos="0 0 0">
    <geom fromto="0.0 0.0 0.0 0.2 -0.2 0.0" name="agent0/aux_4_geom" size="0.08" type="capsule" class="agent0" />
    <body name="agent0/aux_4" pos="0.2 -0.2 0">
      <joint axis="0 0 1" name="agent0/hip_4" pos="0.0 0.0 0.0" range="-30 30" type="hinge" />
      <geom fromto="0.0 0.0 0.0 0.2 -0.2 0.0" name="agent0/rightback_leg_geom" size="0.08" type="capsule" class="agent0" />
      <body pos="0.2 -0.2 0" name="agent0/anon8646907154">
        <joint axis="1 1 0" name="agent0/ankle_4" pos="0.0 0.0 0.0" range="30 70" type="hinge" />
        <geom fromto="0.0 0.0 0.0 0.4 -0.4 0.0" name="agent0/fourth_ankle_geom" size="0.08" type="capsule" class="agent0" />
      </body>
    </body>
  </body>
</body>


<body name="0" pos="0 0 0.75">
      <geom pos="0 0 0" size="0.25" type="sphere"/>
      <joint armature="0" damping="0" limited="false" margin="0.01" name="0_joint" pos="0 0 0" type="free"/>
      <!-- Back right leg -->
      <body name="1" pos="0 0 0">
        <geom density="5.0" fromto="0 0 0 -0.056 0.209 0.125" size="0.04" type="capsule"/>
        <body name="11" pos="-0.056 0.209 0.125">
          <joint axis="0 0 1" name="11_joint" pos="0 0 0" range="-20 20" type="hinge"/>
          <geom density="5.0" fromto="0 0 0 -0.050 0.188 0.113" size="0.04" type="capsule"/>
          <body name="111" pos="-0.050 0.188 0.113">
            <joint axis="0.97 0.26 0" name="111_joint" pos="0 0 0" range="-35 45" type="hinge"/>
            <geom density="5.0" fromto="0 0 0 -0.112 0.418 -0.600" size="0.04" type="capsule"/>
          </body>
        </body>
      </body>
      <!-- Back left leg -->
      <body name="2" pos="0 0 0">
        <geom density="5.0" fromto="0 0 0 0.056 0.209 0.125" size="0.04" type="capsule"/>
        <body name="12" pos="0.056 0.209 0.125">
          <joint axis="0 0 1" name="12_joint" pos="0 0 0" range="-20 20" type="hinge"/>
          <geom density="5.0" fromto="0 0 0 0.050 0.188 0.113" name="back_left_leg_geom" size="0.04" type="capsule"/>
          <body name="112" pos="0.050 0.188 0.113">
            <joint axis="-0.97 0.26 0" name="112_joint" pos="0 0 0" range="-45 35" type="hinge"/>
            <geom density="5.0" fromto="0 0 0 0.112 0.418 -0.600" name="back_left_ankle_geom" size="0.04" type="capsule"/>
          </body>
        </body>
      </body>
      <!-- Middle-back right leg -->
      <body name="3" pos="0 0 0">
        <geom density="5.0" fromto="0 0 0 -0.188 0.108 0.125" name="aux_3_geom" size="0.04" type="capsule"/>
        <body name="13" pos="-0.188 0.108 0.125">
          <joint axis="0 0 1" name="13_joint" pos="0 0 0" range="-20 20" type="hinge"/>
          <geom density="5.0" fromto="0 0 0 -0.170 0.097 0.113" name="middle_back_right_leg_geom" size="0.04" type="capsule"/>
          <body name="113" pos="-0.170 0.097 0.113">
            <joint axis="0.50 0.87 0" name="113_joint" pos="0 0 0" range="-35 45" type="hinge"/>
            <geom density="5.0" fromto="0 0 0 -0.376 0.216 -0.600" name="middle_back_right_ankle_geom" size="0.04" type="capsule"/>
          </body>
        </body>
      </body>
      <!-- Middle-back right leg -->
      <body name="4" pos="0 0 0">
        <geom density="5.0" fromto="0 0 0 0.188 0.108 0.125" name="aux_4_geom" size="0.04" type="capsule"/>
        <body name="14" pos="0.188 0.108 0.125">
          <joint axis="0 0 1" name="14_joint" pos="0 0 0" range="-20 20" type="hinge"/>
          <geom density="5.0" fromto="0 0 0 0.170 0.097 0.113" name="middle_back_left_leg_geom" size="0.04" type="capsule"/>
          <body name="114" pos="0.170 0.097 0.113">
            <joint axis="-0.50 0.87 0" name="114_joint" pos="0 0 0" range="-45 35" type="hinge"/>
            <geom density="5.0" fromto="0 0 0 0.376 0.216 -0.600" name="middle_back_left_ankle_geom" size="0.04" type="capsule"/>
          </body>
        </body>
      </body>
      <!-- Middle-front right leg -->
      <body name="5" pos="0 0 0">
        <geom density="5.0" fromto="0 0 0 -0.209 -0.056 0.125" name="aux_5_geom" size="0.04" type="capsule"/>
        <body name="15" pos="-0.209 -0.056 0.125">
          <joint axis="0 0 1" name="15_joint" pos="0 0 0" range="-20 20" type="hinge"/>
          <geom density="5.0" fromto="0 0 0 -0.188 -0.050 0.113" name="middle_front_right_leg_geom" size="0.04" type="capsule"/>
          <body name="115" pos="-0.188 -0.050 0.113">
            <joint axis="-0.26 0.97 0" name="115_joint" pos="0 0 0" range="-35 45" type="hinge"/>
            <geom density="5.0" fromto="0 0 0 -0.418 -0.112 -0.600" name="middle_front_right_ankle_geom" size="0.04" type="capsule"/>
          </body>
        </body>
      </body>
      <!-- Middle-front right leg -->
      <body name="6" pos="0 0 0">
        <geom density="5.0" fromto="0 0 0 0.209 -0.056 0.125" name="aux_6_geom" size="0.04" type="capsule"/>
        <body name="16" pos="0.209 -0.056 0.125">
          <joint axis="0 0 1" name="16_joint" pos="0 0 0" range="-20 20" type="hinge"/>
          <geom density="5.0" fromto="0 0 0 0.188 -0.050 0.113" name="middle_front_left_leg_geom" size="0.04" type="capsule"/>
          <body name="116" pos="0.188 -0.050 0.113">
            <joint axis="0.26 0.97 0" name="116_joint" pos="0 0 0" range="-45 35" type="hinge"/>
            <geom density="5.0" fromto="0 0 0 0.418 -0.112 -0.600" name="middle_front_left_ankle_geom" size="0.04" type="capsule"/>
          </body>
        </body>
      </body>
      <!-- Front right leg -->
      <body name="7" pos="0 0 0">
        <geom density="5.0" fromto="0 0 0 -0.108 -0.188 0.125" name="aux_7_geom" size="0.04" type="capsule"/>
        <body name="17" pos="-0.108 -0.188 0.125">
          <joint axis="0 0 1" name="17_joint" pos="0 0 0" range="-20 20" type="hinge"/>
          <geom density="5.0" fromto="0 0 0 -0.097 -0.170 0.113" name="front_right_leg_geom" size="0.04" type="capsule"/>
          <body name="117" pos="-0.097 -0.170 0.113">
            <joint axis="-0.87 0.50 0" name="117_joint" pos="0 0 0" range="-35 45" type="hinge"/>
            <geom density="5.0" fromto="0 0 0 -0.216 -0.376 -0.600" name="front_right_ankle_geom" size="0.04" type="capsule"/>
          </body>
        </body>
      </body>
      <!-- Front left leg -->
      <body name="8" pos="0 0 0">
        <geom density="5.0" fromto="0 0 0 0.108 -0.188 0.125" name="aux_8_geom" size="0.04" type="capsule"/>
        <body name="18" pos="0.108 -0.188 0.125">
          <joint axis="0 0 1" name="18_joint" pos="0 0 0" range="-20 20" type="hinge"/>
          <geom density="5.0" fromto="0 0 0 0.097 -0.170 0.113" name="front_left_leg_geom" size="0.04" type="capsule"/>
          <body name="118" pos="0.097 -0.170 0.113">
            <joint axis="0.87 0.50 0" name="118_joint" pos="0 0 0" range="-45 35" type="hinge"/>
            <geom density="5.0" fromto="0 0 0 0.216 -0.376 -0.600" name="front_left_ankle_geom" size="0.04" type="capsule"/>
          </body>
        </body>
      </body>
    </body>
  

  </worldbody>
<actuator>
  <motor ctrllimited="true" ctrlrange="-1.0 1.0" joint="agent0/hip_4" gear="150" class="agent0" />
  <motor ctrllimited="true" ctrlrange="-1.0 1.0" joint="agent0/ankle_4" gear="150" class="agent0" />
  <motor ctrllimited="true" ctrlrange="-1.0 1.0" joint="agent0/hip_1" gear="150" class="agent0" />
  <motor ctrllimited="true" ctrlrange="-1.0 1.0" joint="agent0/ankle_1" gear="150" class="agent0" />
  <motor ctrllimited="true" ctrlrange="-1.0 1.0" joint="agent0/hip_2" gear="150" class="agent0" />
  <motor ctrllimited="true" ctrlrange="-1.0 1.0" joint="agent0/ankle_2" gear="150" class="agent0" />
  <motor ctrllimited="true" ctrlrange="-1.0 1.0" joint="agent0/hip_3" gear="150" class="agent0" />
  <motor ctrllimited="true" ctrlrange="-1.0 1.0" joint="agent0/ankle_3" gear="150" class="agent0" />

  </actuator>

</mujoco>