<mujoco model="mutiagent_world">
  <compiler angle="degree" coordinate="local" inertiafromgeom="true" />
  <option integrator="RK4" timestep="0.01" />
  <default>
    <joint armature="1" damping="1" limited="true" />
  <default class="agent0"><joint armature="1" damping="1" limited="true" />
    <geom conaffinity="1" condim="3" density="5.0" friction="1 0.5 0.5" margin="0.01" rgba="0.5 0.25 0.25 1" />
    <motor ctrllimited="true" ctrlrange="-.4 .4" />
  </default><default class="agent1"><joint armature="1" damping="1" limited="true" />
    <geom conaffinity="1" condim="3" density="5.0" friction="1 0.5 0.5" margin="0.01" rgba="0.25 0.5 0.5 1" />
    <motor ctrllimited="true" ctrlrange="-.4 .4" />
  </default></default>
  <asset>
    <texture builtin="gradient" height="100" rgb1="1 1 1" rgb2="0 0 0" type="skybox" width="100" />
    <texture builtin="flat" height="1278" mark="cross" markrgb="1 1 1" name="texgeom" random="0.01" rgb1="1 1 1" rgb2="0.8 0.6 0.4" type="cube" width="127" />
    <texture builtin="checker" height="100" name="texplane" rgb1="0.1 0.1 0.1" rgb2="0.1 0.1 0.1" type="2d" width="100" markrgb="0.2 0.2 0.2" mark="edge" />
    <material name="MatPlane" reflectance="0.5" shininess="1" specular="1" texrepeat="60 60" texture="texplane" />
    <material name="geom" texture="texgeom" texuniform="true" />
  </asset>
  <worldbody>
    <light cutoff="100" diffuse="1 1 1" dir="-0 0 -1.3" directional="true" exponent="1" pos="0 0 1.3" specular=".1 .1 .1" />
    <geom contype="1" conaffinity="1" friction="1 .1 .1" condim="3" material="MatPlane" name="floor" pos="0 0 0" rgba="1 1 1 1" size="20 20 0.125" type="plane" />
    <geom fromto="4 -5 0  4 +5 0" name="rightgoal" rgba="0.6 0.0 0.0 0" size=".03" type="cylinder" />
    <geom fromto="-4 -5 0  -4 +5 0" name="leftgoal" rgba="0.6 0.0 0.0 0" size=".03" type="cylinder" />
    <geom conaffinity="0xffffffff" condim="3" contype="1" friction="1 .1 .1" name="arena" size="4.5 .25" type="cylinder" pos="0 0 0.25" rgba="0.4 0.4 0.4 0.8" />
  <body name="agent0/torso" pos="-1 0 2.5" euler="0 0 180">
    <geom name="agent0/torso_geom" pos="0 0 0" size="0.25" type="sphere" class="agent0" />
    <joint armature="0" damping="0" limited="false" margin="0.01" name="agent0/root" pos="0 0 0" range="-30 30" type="free" />
    <body name="agent0/1" pos="0 0 0">
        <geom fromto="0.0 0.0 0.0 0.4 0.4 0.0" name="agent0/aux_1_geom" size="0.08" type="capsule" class="agent0" />
        <joint axis="-1 1 0" name="agent0/1_joint" pos="0.0 0.0 0.0" range="-30 30" type="hinge" />
    </body>
    <body name="agent0/2" pos="0 0 0">
        <geom fromto="0.0 0.0 0.0 -0.4 0.4 0.0" name="agent0/aux_2_geom" size="0.08" type="capsule" class="agent0" />
        <joint axis="-1 -1 0" name="agent0/2_joint" pos="0.0 0.0 0.0" range="-30 30" type="hinge" />
    </body>
    <body name="agent0/3" pos="0 0 0">
        <geom fromto="0.0 0.0 0.0 -0.4 -0.4 0.0" name="agent0/aux_3_geom" size="0.08" type="capsule" class="agent0" />
        <joint axis="1 -1 0" name="agent0/3_joint" pos="0.0 0.0 0.0" range="-30 30" type="hinge" />
    </body>
    <body name="agent0/4" pos="0 0 0">
        <geom fromto="0.0 0.0 0.0 0.4 -0.4 0.0" name="agent0/aux_4_geom" size="0.08" type="capsule" class="agent0" />
        <joint axis="1 1 0" name="agent0/4_joint" pos="0.0 0.0 0.0" range="-30 30" type="hinge" />
    </body>
  </body>

  <body name="agent1/torso" pos="1 0 2.5" euler="0 0 180">
    <geom name="agent1/torso_geom" pos="0 0 0" size="0.25" type="sphere" class="agent1" />
    <joint armature="0" damping="0" limited="false" margin="0.01" name="agent1/root" pos="0 0 0" range="-30 30" type="free" />
    <body name="agent1/1" pos="0 0 0">
        <geom fromto="0.0 0.0 0.0 0.4 0.4 0.0" name="agent1/aux_1_geom" size="0.08" type="capsule" class="agent1" />
        <joint axis="-1 1 0" name="agent1/1_joint" pos="0.0 0.0 0.0" range="-30 30" type="hinge" />
    </body>
    <body name="agent1/2" pos="0 0 0">
        <geom fromto="0.0 0.0 0.0 -0.4 0.4 0.0" name="agent1/aux_2_geom" size="0.08" type="capsule" class="agent1" />
        <joint axis="-1 -1 0" name="agent1/2_joint" pos="0.0 0.0 0.0" range="-30 30" type="hinge" />
    </body>
    <body name="agent1/3" pos="0 0 0">
        <geom fromto="0.0 0.0 0.0 -0.4 -0.4 0.0" name="agent1/aux_3_geom" size="0.08" type="capsule" class="agent1" />
        <joint axis="1 -1 0" name="agent1/3_joint" pos="0.0 0.0 0.0" range="-30 30" type="hinge" />
    </body>
    <body name="agent1/4" pos="0 0 0">
        <geom fromto="0.0 0.0 0.0 0.4 -0.4 0.0" name="agent1/aux_4_geom" size="0.08" type="capsule" class="agent1" />
        <joint axis="1 1 0" name="agent1/4_joint" pos="0.0 0.0 0.0" range="-30 30" type="hinge" />
    </body>
  </body>

  </worldbody>
<actuator>
    <motor ctrllimited="true" ctrlrange="-1.0 1.0" joint="agent0/1_joint" gear="150" name="agent0/1_joint" class="agent0" />
    <motor ctrllimited="true" ctrlrange="-1.0 1.0" joint="agent0/2_joint" gear="150" name="agent0/2_joint" class="agent0" />
    <motor ctrllimited="true" ctrlrange="-1.0 1.0" joint="agent0/3_joint" gear="150" name="agent0/3_joint" class="agent0" />
    <motor ctrllimited="true" ctrlrange="-1.0 1.0" joint="agent0/4_joint" gear="150" name="agent0/4_joint" class="agent0" />
  <motor ctrllimited="true" ctrlrange="-1.0 1.0" joint="agent1/1_joint" gear="150" name="agent1/1_joint" class="agent1" />
    <motor ctrllimited="true" ctrlrange="-1.0 1.0" joint="agent1/2_joint" gear="150" name="agent1/2_joint" class="agent1" />
    <motor ctrllimited="true" ctrlrange="-1.0 1.0" joint="agent1/3_joint" gear="150" name="agent1/3_joint" class="agent1" />
    <motor ctrllimited="true" ctrlrange="-1.0 1.0" joint="agent1/4_joint" gear="150" name="agent1/4_joint" class="agent1" />
  </actuator>

</mujoco>